Workbook

Sheet Shared Dashboard - April
B2: Particulars | C2: 45749 | F2: YTM - April-25 | J2: Particulars | K2: 45750 | N2: YTM - April-25 | R2: AIPL SALES DB | S2: 45751 | W2: YTM - April-25 | AB2: AIPL SALES DB | AC2: 45752 | AG2: YTM - April-25 | AL2: AIPL SALES DB | AM2: 45754 | AQ2: YTM - April-25 | AV2: AIPL SALES DB | AW2: 45755 | BA2: YTM - April-25 | BF2: AIPL SALES DB | BG2: 45756 | BK2: YTM - April-25 | BP2: AIPL SALES DB | BQ2: 45757 | BU2: YTM - April-25 | BZ2: AIPL SALES DB | CA2: 45758 | CE2: YTM - April-25 | CJ2: AIPL SALES DB | CK2: 45760 | CO2: YTM - April-25 | CT2: AIPL SALES DB | CU2: 45761 | CY2: YTM - April-25 | DD2: AIPL SALES DB | DE2: 45762 | DI2: YTM - April-25 | DN2: AIPL SALES DB | DO2: 45763 | DS2: YTM - April-25 | DX2: AIPL SALES DB | DY2: 45764 | EC2: YTM - April-25 | EH2: AIPL SALES DB | EI2: 45765 | EM2: YTM - April-25 | ER2: AIPL SALES DB | ES2: 45767 | EW2: YTM - April-25 | FB2: AIPL SALES DB | FC2: 45768 | FG2: YTM - April-25 | FL2: AIPL SALES DB | FM2: 45769 | FQ2: YTM - April-25 | FV2: AIPL SALES DB | FW2: 45770 | GA2: YTM - April-25 | GF2: AIPL SALES DB | GG2: 45771 | GL2: YTM - April-25 | GR2: AIPL SALES DB | GS2: 45772 | GX2: YTM - April-25 | HD2: AIPL SALES DB | HE2: 45774 | HJ2: YTM - April-25 | HP2: AIPL SALES DB | HQ2: 45775 | HV2: YTM - April-25 | IB2: AIPL SALES DB | IC2: 45776 | IH2: YTM - April-25 | IN2: AIPL SALES DB | IO2: 45777 | IT2: YTM - April-25
B3: Product | C3: PCB-Ref | D3: PCB- CF | E3: Total | F3: PCB-Ref | G3: PCB- CF | H3: Total | J3: Product | K3: PCB - Ref | L3: PCB - CF | M3: Total | N3: PCB - Ref | O3: PCB - CF | P3: Total | R3: Product | S3: PCB - Ref | T3: PCB - CF | U3: Stator - CF | V3: Total | W3: PCB - Ref | X3: PCB - CF | Y3: Stator - CF | Z3: Total | AB3: Product | AC3: PCB - Ref | AD3: PCB - CF | AE3: Stator - CF | AF3: Total | AG3: PCB - Ref | AH3: PCB - CF | AI3: Stator - CF | AJ3: Total | AL3: Product | AM3: PCB - Ref | AN3: PCB - CF | AO3: Stator - CF | AP3: Total | AQ3: PCB - Ref | AR3: PCB - CF | AS3: Stator - CF | AT3: Total | AV3: Product | AW3: PCB - Ref | AX3: PCB - CF | AY3: Stator - CF | AZ3: Total | BA3: PCB - Ref | BB3: PCB - CF | BC3: Stator - CF | BD3: Total | BF3: Product | BG3: PCB - Ref | BH3: PCB - CF | BI3: Stator - CF | BJ3: Total | BK3: PCB - Ref | BL3: PCB - CF | BM3: Stator - CF | BN3: Total | BP3: Product | BQ3: PCB - Ref | BR3: PCB - CF | BS3: Stator - CF | BT3: Total | BU3: PCB - Ref | BV3: PCB - CF | BW3: Stator - CF | BX3: Total | BZ3: Product | CA3: PCB - Ref | CB3: PCB - CF | CC3: Stator - CF | CD3: Total | CE3: PCB - Ref | CF3: PCB - CF | CG3: Stator - CF | CH3: Total | CJ3: Product | CK3: PCB - Ref | CL3: PCB - CF | CM3: Stator - CF | CN3: Total | CO3: PCB - Ref | CP3: PCB - CF | CQ3: Stator - CF | CR3: Total | CT3: Product | CU3: PCB - Ref | CV3: PCB - CF | CW3: Stator - CF | CX3: Total | CY3: PCB - Ref | CZ3: PCB - CF | DA3: Stator - CF | DB3: Total | DD3: Product | DE3: PCB - Ref | DF3: PCB - CF | DG3: Stator - CF | DH3: Total | DI3: PCB - Ref | DJ3: PCB - CF | DK3: Stator - CF | DL3: Total | DN3: Product | DO3: PCB - Ref | DP3: PCB - CF | DQ3: Stator - CF | DR3: Total | DS3: PCB - Ref | DT3: PCB - CF | DU3: Stator - CF | DV3: Total | DX3: Product | DY3: PCB - Ref | DZ3: PCB - CF | EA3: Stator - CF | EB3: Total | EC3: PCB - Ref | ED3: PCB - CF | EE3: Stator - CF | EF3: Total | EH3: Product | EI3: PCB - Ref | EJ3: PCB - CF | EK3: Stator - CF | EL3: Total | EM3: PCB - Ref | EN3: PCB - CF | EO3: Stator - CF | EP3: Total | ER3: Product | ES3: PCB - Ref | ET3: PCB - CF | EU3: Stator - CF | EV3: Total | EW3: PCB - Ref | EX3: PCB - CF | EY3: Stator - CF | EZ3: Total | FB3: Product | FC3: PCB - Ref | FD3: PCB - CF | FE3: Stator - CF | FF3: Total | FG3: PCB - Ref | FH3: PCB - CF | FI3: Stator - CF | FJ3: Total | FL3: Product | FM3: PCB - Ref | FN3: PCB - CF | FO3: Stator - CF | FP3: Total | FQ3: PCB - Ref | FR3: PCB - CF | FS3: Stator - CF | FT3: Total | FV3: Product | FW3: PCB - Ref | FX3: PCB - CF | FY3: Stator - CF | FZ3: Total | GA3: PCB - Ref | GB3: PCB - CF | GC3: Stator - CF | GD3: Total | GF3: Product | GG3: PCB - Ref | GH3: PCB - CF | GI3: PCB - MG | GJ3: Stator - CF | GK3: Total | GL3: PCB - Ref | GM3: PCB - CF | GN3: PCB - MG | GO3: Stator - CF | GP3: Total | GR3: Product | GS3: PCB - Ref | GT3: PCB - CF | GU3: PCB - MG | GV3: Stator - CF | GW3: Total | GX3: PCB - Ref | GY3: PCB - CF | GZ3: PCB - MG | HA3: Stator - CF | HB3: Total | HD3: Product | HE3: PCB - Ref | HF3: PCB - CF | HG3: PCB - MG | HH3: Stator - CF | HI3: Total | HJ3: PCB - Ref | HK3: PCB - CF | HL3: PCB - MG | HM3: Stator - CF | HN3: Total | HP3: Product | HQ3: PCB - Ref | HR3: PCB - CF | HS3: PCB - MG | HT3: Stator - CF | HU3: Total | HV3: PCB - Ref | HW3: PCB - CF | HX3: PCB - MG | HY3: Stator - CF | HZ3: Total | IB3: Product | IC3: PCB - Ref | ID3: PCB - CF | IE3: PCB - MG | IF3: Stator - CF | IG3: Total | IH3: PCB - Ref | II3: PCB - CF | IJ3: PCB - MG | IK3: Stator - CF | IL3: Total | IN3: Product | IO3: PCB - Ref | IP3: PCB - CF | IQ3: PCB - MG | IR3: Stator - CF | IS3: Total | IT3: PCB - Ref | IU3: PCB - CF | IV3: PCB - MG | IW3: Stator - CF | IX3: Total
B4: Qty | C4: 500 | D4: 0 | E4: 500 | F4: 500 | G4: 0 | H4: 500 | J4: Qty | K4: 0 | L4: 50 | M4: 50 | N4: 500 | O4: 50 | P4: 550 | R4: Qty | S4: 463 | T4: 14930 | U4: 100 | V4: 15493 | W4: 963 | X4: 14980 | Y4: 100 | Z4: 16043 | AB4: Qty | AC4: 0 | AD4: 6720 | AE4: 0 | AF4: 6720 | AG4: 963 | AH4: 21700 | AI4: 100 | AJ4: 22763 | AL4: Qty | AM4: 0 | AN4: 7140 | AO4: 0 | AP4: 7140 | AQ4: 963 | AR4: 28840 | AS4: 100 | AT4: 29903 | AV4: Qty | AW4: 0 | AX4: 13930 | AY4: 0 | AZ4: 13930 | BA4: 963 | BB4: 42770 | BC4: 100 | BD4: 43833 | BF4: Qty | BG4: 3000 | BH4: 8450 | BI4: 0 | BJ4: 11450 | BK4: 3963 | BL4: 51220 | BM4: 100 | BN4: 55283 | BP4: Qty | BQ4: 0 | BR4: 0 | BS4: 453 | BT4: 453 | BU4: 3963 | BV4: 51220 | BW4: 553 | BX4: 55736 | BZ4: Qty | CA4: 5000 | CB4: 15960 | CC4: 0 | CD4: 20960 | CE4: 8963 | CF4: 67180 | CG4: 553 | CH4: 76696 | CJ4: Qty | CK4: 0 | CL4: 2660 | CM4: 0 | CN4: 2660 | CO4: 8963 | CP4: 69840 | CQ4: 553 | CR4: 79356 | CT4: Qty | CU4: 0 | CV4: 7140 | CW4: 0 | CX4: 7140 | CY4: 8963 | CZ4: 76980 | DA4: 553 | DB4: 86496 | DD4: Qty | DE4: 0 | DF4: 5040 | DG4: 0 | DH4: 5040 | DI4: 8963 | DJ4: 82020 | DK4: 553 | DL4: 91536 | DN4: Qty | DO4: 0 | DP4: 8400 | DQ4: 2240 | DR4: 10640 | DS4: 8963 | DT4: 90420 | DU4: 2793 | DV4: 102176 | DX4: Qty | DY4: 0 | DZ4: 8400 | EA4: 1760 | EB4: 10160 | EC4: 8963 | ED4: 98820 | EE4: 4553 | EF4: 112336 | EH4: Qty | EI4: 0 | EJ4: 7630 | EK4: 2716 | EL4: 10346 | EM4: 8963 | EN4: 106450 | EO4: 7269 | EP4: 122682 | ER4: Qty | ES4: 4000 | ET4: 6720 | EU4: 0 | EV4: 10720 | EW4: 13418 | EX4: 112715 | EY4: 7269 | EZ4: 133402 | FB4: Qty | FC4: 0 | FD4: 5040 | FE4: 2232 | FF4: 7272 | FG4: 13418 | FH4: 117755 | FI4: 9501 | FJ4: 140674 | FL4: Qty | FM4: 0 | FN4: 5880 | FO4: 3840 | FP4: 9720 | FQ4: 12963 | FR4: 124090 | FS4: 13341 | FT4: 150394 | FV4: Qty | FW4: 0 | FX4: 8470 | FY4: 3300 | FZ4: 11770 | GA4: 12963 | GB4: 132560 | GC4: 16641 | GD4: 162164 | GF4: Qty | GG4: 0 | GH4: 5040 | GI4: 900 | GJ4: 900 | GK4: 6840 | GL4: 12963 | GM4: 137600 | GN4: 900 | GO4: 17541 | GP4: 169004 | GR4: Qty | GS4: 3797 | GT4: 6720 | GU4: 1155 | GV4: 1200 | GW4: 12872 | GX4: 16760 | GY4: 144320 | GZ4: 2055 | HA4: 18741 | HB4: 181876 | HD4: Qty | HE4: 3000 | HF4: 7560 | HG4: 447 | HH4: 2870 | HI4: 13877 | HJ4: 19760 | HK4: 151880 | HL4: 2502 | HM4: 21611 | HN4: 195753 | HP4: Qty | HQ4: 0 | HR4: 12339 | HS4: 210 | HT4: 2907 | HU4: 15456 | HV4: 19760 | HW4: 164219 | HX4: 2712 | HY4: 24518 | HZ4: 211209 | IB4: Qty | IC4: 0 | ID4: 96 | IE4: 360 | IF4: 2540 | IG4: 2996 | IH4: 19760 | II4: 164315 | IJ4: 3072 | IK4: 27058 | IL4: 214205 | IN4: Qty | IO4: 0 | IP4: 8400 | IQ4: 175 | IR4: 2000 | IS4: 10575 | IT4: 19760 | IU4: 172715 | IV4: 3247 | IW4: 29058 | IX4: 224780
B5: Sales | C5: 369655 | D5: 0 | E5: 369655 | F5: 369655 | G5: 0 | H5: 369655 | J5: Sales | K5: 0 | L5: 23950 | M5: 23950 | N5: 369655 | O5: 23950 | P5: 393605 | R5: Sales | S5: 340911.53 | T5: 5628013.3 | U5: 18123.5 | V5: 5987048.4 | W5: 710566.53 | X5: 5651963.3 | Y5: 18123.5 | Z5: 6380653.4 | AB5: Sales | AC5: 0 | AD5: 2406297.6 | AE5: 0 | AF5: 2406297.6 | AG5: 710566.53 | AH5: 8058260.9 | AI5: 18123.5 | AJ5: 8786951 | AL5: Sales | AM5: 0 | AN5: 2542982.4 | AO5: 0 | AP5: 2542982.4 | AQ5: 710566.53 | AR5: 10601243 | AS5: 18123.5 | AT5: 11329933 | AV5: Sales | AW5: 0 | AX5: 4941988.8 | AY5: 0 | AZ5: 4941988.8 | BA5: 710566.53 | BB5: 15543232 | BC5: 18123.5 | BD5: 16271922 | BF5: Sales | BG5: 2208930 | BH5: 3009552 | BI5: 0 | BJ5: 5218482 | BK5: 2919496.5 | BL5: 18552784 | BM5: 18123.5 | BN5: 21490404 | BP5: Sales | BQ5: 0 | BR5: 0 | BS5: 94115.28 | BT5: 94115.28 | BU5: 2919496.5 | BV5: 18552784 | BW5: 112238.78 | BX5: 21584519 | BZ5: Sales | CA5: 3696550 | CB5: 5674233.6 | CC5: 0 | CD5: 9370783.6 | CE5: 6616046.5 | CF5: 24227018 | CG5: 112238.78 | CH5: 30955303 | CJ5: Sales | CK5: 0 | CL5: 947385.6 | CM5: 0 | CN5: 947385.6 | CO5: 6616046.5 | CP5: 25174403 | CQ5: 112238.78 | CR5: 31902689 | CT5: Sales | CU5: 0 | CV5: 2542982.4 | CW5: 0 | CX5: 2542982.4 | CY5: 6616046.5 | CZ5: 27717386 | DA5: 112238.78 | DB5: 34445671 | DD5: Sales | DE5: 0 | DF5: 1795046.4 | DG5: 0 | DH5: 1795046.4 | DI5: 6616046.5 | DJ5: 29512432 | DK5: 112238.78 | DL5: 36240717 | DN5: Sales | DO5: 0 | DP5: 3004646.4 | DQ5: 346550.4 | DR5: 3351196.8 | DS5: 6616046.5 | DT5: 32517079 | DU5: 458789.18 | DV5: 39591914 | DX5: Sales | DY5: 0 | DZ5: 2998195.2 | EA5: 272289.6 | EB5: 3270484.8 | EC5: 6616046.5 | ED5: 35515274 | EE5: 731078.78 | EF5: 42862399 | EH5: Sales | EI5: 0 | EJ5: 2715680.8 | EK5: 420192.36 | EL5: 3135873.2 | EM5: 6616046.5 | EN5: 38230955 | EO5: 1151271.1 | EP5: 45998272 | ER5: Sales | ES5: 2957240 | ET5: 2393395.2 | EU5: 0 | EV5: 5350635.2 | EW5: 9733519.3 | EX5: 40464117 | EY5: 1151271.1 | EZ5: 51348907 | FB5: Sales | FC5: 0 | FD5: 1795046.4 | FE5: 345312.72 | FF5: 2140359.1 | FG5: 9733519.3 | FH5: 42259163 | FI5: 1496583.9 | FJ5: 53489267 | FL5: Sales | FM5: 0 | FN5: 2110214.4 | FO5: 594086.4 | FP5: 2704300.8 | FQ5: 9573286.5 | FR5: 44529611 | FS5: 2090670.3 | FT5: 56193567 | FV5: Sales | FW5: 0 | FX5: 3024772.8 | FY5: 510543 | FZ5: 3535315.8 | GA5: 9573286.5 | GB5: 47554383 | GC5: 2601213.3 | GD5: 59728883 | GF5: Sales | GG5: 0 | GH5: 1795046.4 | GI5: 416650.5 | GJ5: 139239 | GK5: 2350935.9 | GL5: 9573286.5 | GM5: 49349430 | GN5: 416650.5 | GO5: 2740452.3 | GP5: 62079819 | GR5: Sales | GS5: 2795760.1 | GT5: 2393395.2 | GU5: 821733.15 | GV5: 185652 | GW5: 6196540.4 | GX5: 12369047 | GY5: 51742825 | GZ5: 1238383.6 | HA5: 2926104.3 | HB5: 68276359 | HD5: Sales | HE5: 2217930 | HF5: 2935044 | HG5: 293091.99 | HH5: 444017.7 | HI5: 5890083.7 | HJ5: 14586977 | HK5: 54677869 | HL5: 1531475.6 | HM5: 3370122 | HN5: 74166443 | HP5: Sales | HQ5: 0 | HR5: 4261132.8 | HS5: 64967.7 | HT5: 425710.32 | HU5: 4751810.8 | HV5: 14586977 | HW5: 58939002 | HX5: 1596443.3 | HY5: 3795832.3 | HZ5: 78918254 | IB5: Sales | IC5: 0 | ID5: 45984 | IE5: 111373.2 | IF5: 392963.4 | IG5: 550320.6 | IH5: 14586977 | II5: 58984986 | IJ5: 1707816.5 | IK5: 4188795.7 | IL5: 79468575 | IN5: Sales | IO5: 0 | IP5: 2971584 | IQ5: 54139.75 | IR5: 309420 | IS5: 3335143.8 | IT5: 14586977 | IU5: 61956570 | IV5: 1761956.3 | IW5: 4498215.7 | IX5: 82803718
B6: COGS | C6: 284150 | D6: 0 | E6: 284150 | F6: 284150 | G6: 0 | H6: 284150 | J6: COGS | K6: 0 | L6: 23124.5 | M6: 23124.5 | N6: 284150 | O6: 23124.5 | P6: 307274.5 | R6: COGS | S6: 263122.9 | T6: 5319618.5 | U6: 18522 | V6: 5601263.4 | W6: 547272.9 | X6: 5342743 | Y6: 18522 | Z6: 5908537.9 | AB6: COGS | AC6: 0 | AD6: 2265513.6 | AE6: 0 | AF6: 2265513.6 | AG6: 547272.9 | AH6: 7608256.6 | AI6: 18522 | AJ6: 8174051.5 | AL6: COGS | AM6: 0 | AN6: 2390551.8 | AO6: 0 | AP6: 2390551.8 | AQ6: 547272.9 | AR6: 9998808.4 | AS6: 18522 | AT6: 10564603 | AV6: COGS | AW6: 0 | AX6: 4651753.4 | AY6: 0 | AZ6: 4651753.4 | BA6: 547272.9 | BB6: 14650562 | BC6: 18522 | BD6: 15216357 | BF6: COGS | BG6: 1449630 | BH6: 2829271 | BI6: 0 | BJ6: 4278901 | BK6: 1996902.9 | BL6: 17479833 | BM6: 18522 | BN6: 19495258 | BP6: COGS | BQ6: 0 | BR6: 0 | BS6: 96339.51 | BT6: 96339.51 | BU6: 1996902.9 | BV6: 17479833 | BW6: 114861.51 | BX6: 19591597 | BZ6: COGS | CA6: 2416050 | CB6: 5338082.4 | CC6: 0 | CD6: 7754132.4 | CE6: 4412952.9 | CF6: 22817915 | CG6: 114861.51 | CH6: 27345730 | CJ6: COGS | CK6: 0 | CL6: 890541.4 | CM6: 0 | CN6: 890541.4 | CO6: 4412952.9 | CP6: 23708457 | CQ6: 114861.51 | CR6: 28236271 | CT6: COGS | CU6: 0 | CV6: 2390561.2 | CW6: 0 | CX6: 2390561.2 | CY6: 4412952.9 | CZ6: 26099018 | DA6: 114861.51 | DB6: 30626832 | DD6: COGS | DE6: 0 | DF6: 1687492.8 | DG6: 0 | DH6: 1687492.8 | DI6: 4412952.9 | DJ6: 27786511 | DK6: 114861.51 | DL6: 32314325 | DN6: COGS | DO6: 0 | DP6: 2828011.2 | DQ6: 353404.8 | DR6: 3181416 | DS6: 4412952.9 | DT6: 30614522 | DU6: 468266.31 | DV6: 35495741 | DX6: COGS | DY6: 0 | DZ6: 2820199.2 | EA6: 277675.2 | EB6: 3097874.4 | EC6: 4412952.9 | ED6: 33434721 | EE6: 745941.51 | EF6: 38593615 | EH6: COGS | EI6: 0 | EJ6: 2555618.1 | EK6: 428503.32 | EL6: 2984121.4 | EM6: 4412952.9 | EN6: 35990339 | EO6: 1174444.8 | EP6: 41577737 | ER6: COGS | ES6: 1932840 | ET6: 2249940 | EU6: 0 | EV6: 4182780 | EW6: 6499141.6 | EX6: 38086931 | EY6: 1174444.8 | EZ6: 45760517 | FB6: COGS | FC6: 0 | FD6: 1687492.8 | FE6: 352142.64 | FF6: 2039635.4 | FG6: 6499141.6 | FH6: 39774423 | FI6: 1526587.5 | FJ6: 47800152 | FL6: COGS | FM6: 0 | FN6: 2045013.6 | FO6: 605836.8 | FP6: 2650850.4 | FQ6: 6345792.9 | FR6: 41972786 | FS6: 2132424.3 | FT6: 50451003 | FV6: COGS | FW6: 0 | FX6: 2907121.7 | FY6: 520641 | FZ6: 3427762.7 | GA6: 6345792.9 | GB6: 44879907 | GC6: 2653065.3 | GD6: 53878765 | GF6: COGS | GG6: 0 | GH6: 1687492.8 | GI6: 441709.5 | GJ6: 141993 | GK6: 2271195.3 | GL6: 6345792.9 | GM6: 46567400 | GN6: 441709.5 | GO6: 2795058.3 | GP6: 56149961 | GR6: COGS | GS6: 1837647.6 | GT6: 2250032.4 | GU6: 770503.65 | GV6: 189324 | GW6: 5047507.7 | GX6: 8183440.5 | GY6: 48817432 | GZ6: 1212213.1 | HA6: 2984382.3 | HB6: 61197468 | HD6: COGS | HE6: 1449630 | HF6: 2824021.2 | HG6: 280508.01 | HH6: 452799.9 | HI6: 5006959.1 | HJ6: 9633070.5 | HK6: 51641454 | HL6: 1492721.2 | HM6: 3437182.2 | HN6: 66204428 | HP6: COGS | HQ6: 0 | HR6: 4000582.1 | HS6: 80184.3 | HT6: 433767.69 | HU6: 4514534.1 | HV6: 9630171.3 | HW6: 55642036 | HX6: 1572905.5 | HY6: 3870949.9 | HZ6: 70716062 | IB6: COGS | IC6: 0 | ID6: 44399.04 | IE6: 137458.8 | IF6: 400735.8 | IG6: 582593.64 | IH6: 9630171.3 | II6: 55686435 | IJ6: 1710364.3 | IK6: 4271685.7 | IL6: 71298656 | IN6: COGS | IO6: 0 | IP6: 2799417.6 | IQ6: 66820.25 | IR6: 315540 | IS6: 3181777.9 | IT6: 9630171.3 | IU6: 58485852 | IV6: 1777184.5 | IW6: 4587225.7 | IX6: 74480434
B7: BOM cost | C7: 255890 | D7: 0 | E7: 255890 | F7: 255890 | G7: 0 | H7: 255890 | J7: BOM cost | K7: 0 | L7: 20452.5 | M7: 20452.5 | N7: 255890 | O7: 20452.5 | P7: 276342.5 | R7: BOM cost | S7: 236954.14 | T7: 4521759.3 | U7: 16472 | V7: 4775185.4 | W7: 492844.14 | X7: 4542211.8 | Y7: 16472 | Z7: 5051527.9 | AB7: BOM cost | AC7: 0 | AD7: 1906396.8 | AE7: 0 | AF7: 1906396.8 | AG7: 492844.14 | AH7: 6448608.6 | AI7: 16472 | AJ7: 6957924.7 | AL7: BOM cost | AM7: 0 | AN7: 2008990.2 | AO7: 0 | AP7: 2008990.2 | AQ7: 492844.14 | AR7: 8457598.8 | AS7: 16472 | AT7: 8966914.9 | AV7: BOM cost | AW7: 0 | AX7: 3907334.2 | AY7: 0 | AZ7: 3907334.2 | BA7: 492844.14 | BB7: 12364933 | BC7: 16472 | BD7: 12874249 | BF7: BOM cost | BG7: 1280070 | BH7: 2377703 | BI7: 0 | BJ7: 3657773 | BK7: 1772914.1 | BL7: 14742636 | BM7: 16472 | BN7: 16532022 | BP7: BOM cost | BQ7: 0 | BR7: 0 | BS7: 87053.01 | BT7: 87053.01 | BU7: 1772914.1 | BV7: 14742636 | BW7: 103525.01 | BX7: 16619075 | BZ7: BOM cost | CA7: 2133450 | CB7: 4485180 | CC7: 0 | CD7: 6618630 | CE7: 3906364.1 | CF7: 19227816 | CG7: 103525.01 | CH7: 23237705 | CJ7: BOM cost | CK7: 0 | CL7: 748391 | CM7: 0 | CN7: 748391 | CO7: 3906364.1 | CP7: 19976207 | CQ7: 103525.01 | CR7: 23986096 | CT7: BOM cost | CU7: 0 | CV7: 2008999.6 | CW7: 0 | CX7: 2008999.6 | CY7: 3906364.1 | CZ7: 21985207 | DA7: 103525.01 | DB7: 25995096 | DD7: BOM cost | DE7: 0 | DF7: 1418155.2 | DG7: 0 | DH7: 1418155.2 | DI7: 3906364.1 | DJ7: 23403362 | DK7: 103525.01 | DL7: 27413251 | DN7: BOM cost | DO7: 0 | DP7: 2379115.2 | DQ7: 307484.8 | DR7: 2686600 | DS7: 3906364.1 | DT7: 25782477 | DU7: 411009.81 | DV7: 30099851 | DX7: BOM cost | DY7: 0 | DZ7: 2371303.2 | EA7: 241595.2 | EB7: 2612898.4 | EC7: 3906364.1 | ED7: 28153780 | EE7: 652605.01 | EF7: 32712749 | EH7: BOM cost | EI7: 0 | EJ7: 2147588.8 | EK7: 372825.32 | EL7: 2520414.1 | EM7: 3906364.1 | EN7: 30301369 | EO7: 1025430.3 | EP7: 35233164 | ER7: BOM cost | ES7: 1706760 | ET7: 1890823.2 | EU7: 0 | EV7: 3597583.2 | EW7: 5741875.5 | EX7: 32063441 | EY7: 1025430.3 | EZ7: 38830747 | FB7: BOM cost | FC7: 0 | FD7: 1418155.2 | FE7: 306386.64 | FF7: 1724541.8 | FG7: 5741875.5 | FH7: 33481596 | FI7: 1331817 | FJ7: 40555289 | FL7: BOM cost | FM7: 0 | FN7: 1685157.6 | FO7: 527116.8 | FP7: 2212274.4 | FQ7: 5613124.1 | FR7: 35295505 | FS7: 1858933.8 | FT7: 42767563 | FV7: BOM cost | FW7: 0 | FX7: 2408465.5 | FY7: 452991 | FZ7: 2861456.5 | GA7: 5613124.1 | GB7: 37703971 | GC7: 2311924.8 | GD7: 45629019 | GF7: BOM cost | GG7: 0 | GH7: 1418155.2 | GI7: 392071 | GJ7: 123543 | GK7: 1933769.2 | GL7: 5613124.1 | GM7: 39122126 | GN7: 392071 | GO7: 2435467.8 | GP7: 47562789 | GR7: BOM cost | GS7: 1620141.9 | GT7: 1890915.6 | GU7: 703597.65 | GV7: 164724 | GW7: 4379379.2 | GX7: 7233266.1 | GY7: 41013041 | GZ7: 1095668.6 | HA7: 2600191.8 | HB7: 51942168 | HD7: BOM cost | HE7: 1280070 | HF7: 2374906.8 | HG7: 254892.73 | HH7: 393964.9 | HI7: 4303834.4 | HJ7: 8513336.1 | HK7: 43387948 | HL7: 1350561.4 | HM7: 2994156.7 | HN7: 56246002 | HP7: BOM cost | HQ7: 0 | HR7: 3341186 | HS7: 68961.9 | HT7: 374174.19 | HU7: 3784322 | HV7: 8513336.1 | HW7: 46729134 | HX7: 1419523.3 | HY7: 3368330.9 | HZ7: 60030324 | IB7: BOM cost | IC7: 0 | ID7: 39268.8 | IE7: 118220.4 | IF7: 348665.8 | IG7: 506155 | IH7: 8513336.1 | II7: 46768403 | IJ7: 1537743.7 | IK7: 3716996.7 | IL7: 60536479 | IN7: BOM cost | IO7: 0 | IP7: 2350521.6 | IQ7: 57468.25 | IR7: 274540 | IS7: 2682529.9 | IT7: 8513336.1 | IU7: 49118924 | IV7: 1595211.9 | IW7: 3991536.7 | IX7: 63219009
B8: Labour Cost | C8: 20505 | D8: 0 | E8: 20505 | F8: 20505 | G8: 0 | H8: 20505 | J8: Labour Cost | K8: 0 | L8: 1936.5 | M8: 1936.5 | N8: 20505 | O8: 1936.5 | P8: 22441.5 | R8: Labour Cost | S8: 18987.63 | T8: 578238.9 | U8: 1243 | V8: 598469.53 | W8: 39492.63 | X8: 580175.4 | Y8: 1243 | Z8: 620911.03 | AB8: Labour Cost | AC8: 0 | AD8: 260265.6 | AE8: 0 | AF8: 260265.6 | AG8: 39492.63 | AH8: 840441 | AI8: 1243 | AJ8: 881176.63 | AL8: Labour Cost | AM8: 0 | AN8: 276532.2 | AO8: 0 | AP8: 276532.2 | AQ8: 39492.63 | AR8: 1116973.2 | AS8: 1243 | AT8: 1157708.8 | AV8: Labour Cost | AW8: 0 | AX8: 539508.9 | AY8: 0 | AZ8: 539508.9 | BA8: 39492.63 | BB8: 1656482.1 | BC8: 1243 | BD8: 1697217.7 | BF8: Labour Cost | BG8: 123030 | BH8: 327268.5 | BI8: 0 | BJ8: 450298.5 | BK8: 162522.63 | BL8: 1983750.6 | BM8: 1243 | BN8: 2147516.2 | BP8: Labour Cost | BQ8: 0 | BR8: 0 | BS8: 5630.79 | BT8: 5630.79 | BU8: 162522.63 | BV8: 1983750.6 | BW8: 6873.79 | BX8: 2153147 | BZ8: Labour Cost | CA8: 205050 | CB8: 618130.8 | CC8: 0 | CD8: 823180.8 | CE8: 367572.63 | CF8: 2601881.4 | CG8: 6873.79 | CH8: 2976327.8 | CJ8: Labour Cost | CK8: 0 | CL8: 103021.8 | CM8: 0 | CN8: 103021.8 | CO8: 367572.63 | CP8: 2704903.2 | CQ8: 6873.79 | CR8: 3079349.6 | CT8: Labour Cost | CU8: 0 | CV8: 276532.2 | CW8: 0 | CX8: 276532.2 | CY8: 367572.63 | CZ8: 2981435.4 | DA8: 6873.79 | DB8: 3355881.8 | DD8: Labour Cost | DE8: 0 | DF8: 195199.2 | DG8: 0 | DH8: 195199.2 | DI8: 367572.63 | DJ8: 3176634.6 | DK8: 6873.79 | DL8: 3551081 | DN8: Labour Cost | DO8: 0 | DP8: 325332 | DQ8: 27843.2 | DR8: 353175.2 | DS8: 367572.63 | DT8: 3501966.6 | DU8: 34716.99 | DV8: 3904256.2 | DX8: Labour Cost | DY8: 0 | DZ8: 325332 | EA8: 21876.8 | EB8: 347208.8 | EC8: 367572.63 | ED8: 3827298.6 | EE8: 56593.79 | EF8: 4251465 | EH8: Labour Cost | EI8: 0 | EJ8: 295719.2 | EK8: 33759.88 | EL8: 329479.08 | EM8: 367572.63 | EN8: 4123017.8 | EO8: 90353.67 | EP8: 4580944.1 | ER8: Labour Cost | ES8: 164040 | ET8: 260265.6 | EU8: 0 | EV8: 424305.6 | EW8: 549444.08 | EX8: 4365452 | EY8: 90353.67 | EZ8: 5005249.7 | FB8: Labour Cost | FC8: 0 | FD8: 195199.2 | FE8: 27743.76 | FF8: 222942.96 | FG8: 549444.08 | FH8: 4560651.2 | FI8: 118097.43 | FJ8: 5228192.7 | FL8: Labour Cost | FM8: 0 | FN8: 259039.2 | FO8: 47731.2 | FP8: 306770.4 | FQ8: 531612.63 | FR8: 4837521.8 | FS8: 165828.63 | FT8: 5534963.1 | FV8: Labour Cost | FW8: 0 | FX8: 359639.7 | FY8: 41019 | FZ8: 400658.7 | GA8: 531612.63 | GB8: 5197161.5 | GC8: 206847.63 | GD8: 5935621.8 | GF8: Labour Cost | GG8: 0 | GH8: 195199.2 | GI8: 35994.5 | GJ8: 11187 | GK8: 242380.7 | GL8: 531612.63 | GM8: 5392360.7 | GN8: 35994.5 | GO8: 218034.63 | GP8: 6178002.5 | GR8: Labour Cost | GS8: 155714.97 | GT8: 260265.6 | GU8: 48555.15 | GV8: 14916 | GW8: 479451.72 | GX8: 687327.6 | GY8: 5652626.3 | GZ8: 84549.65 | HA8: 232950.63 | HB8: 6657454.2 | HD8: Labour Cost | HE8: 123030 | HF8: 323719.2 | HG8: 18586.31 | HH8: 35674.1 | HI8: 501009.61 | HJ8: 810357.6 | HK8: 5976345.5 | HL8: 103135.96 | HM8: 268624.73 | HN8: 7158463.8 | HP8: Labour Cost | HQ8: 0 | HR8: 477889.47 | HS8: 8133.3 | HT8: 36134.01 | HU8: 522156.78 | HV8: 810357.6 | HW8: 6454235 | HX8: 111269.26 | HY8: 304758.74 | HZ8: 7680620.6 | IB8: Labour Cost | IC8: 0 | ID8: 3718.08 | IE8: 13942.8 | IF8: 31572.2 | IG8: 49233.08 | IH8: 810357.6 | II8: 6457953.1 | IJ8: 125212.06 | IK8: 336330.94 | IL8: 7729853.7 | IN8: Labour Cost | IO8: 0 | IP8: 325332 | IQ8: 6777.75 | IR8: 24860 | IS8: 356969.75 | IT8: 810357.6 | IU8: 6783285 | IV8: 131989.81 | IW8: 361190.94 | IX8: 8086823.4
B9: Other Conv Cost | C9: 7760 | D9: 0 | E9: 7760 | F9: 7760 | G9: 0 | H9: 7760 | J9: Other Conv Cost | K9: 0 | L9: 735.5 | M9: 735.5 | N9: 7760 | O9: 735.5 | P9: 8495.5 | R9: Other Conv Cost | S9: 7185.76 | T9: 219620.3 | U9: 807 | V9: 227613.06 | W9: 14945.76 | X9: 220355.8 | Y9: 807 | Z9: 236108.56 | AB9: Other Conv Cost | AC9: 0 | AD9: 98851.2 | AE9: 0 | AF9: 98851.2 | AG9: 14945.76 | AH9: 319207 | AI9: 807 | AJ9: 334959.76 | AL9: Other Conv Cost | AM9: 0 | AN9: 105029.4 | AO9: 0 | AP9: 105029.4 | AQ9: 14945.76 | AR9: 424236.4 | AS9: 807 | AT9: 439989.16 | AV9: Other Conv Cost | AW9: 0 | AX9: 204910.3 | AY9: 0 | AZ9: 204910.3 | BA9: 14945.76 | BB9: 629146.7 | BC9: 807 | BD9: 644899.46 | BF9: Other Conv Cost | BG9: 46560 | BH9: 124299.5 | BI9: 0 | BJ9: 170859.5 | BK9: 61505.76 | BL9: 753446.2 | BM9: 807 | BN9: 815758.96 | BP9: Other Conv Cost | BQ9: 0 | BR9: 0 | BS9: 3655.71 | BT9: 3655.71 | BU9: 61505.76 | BV9: 753446.2 | BW9: 4462.71 | BX9: 819414.67 | BZ9: Other Conv Cost | CA9: 77600 | CB9: 234771.6 | CC9: 0 | CD9: 312371.6 | CE9: 139105.76 | CF9: 988217.8 | CG9: 4462.71 | CH9: 1131786.3 | CJ9: Other Conv Cost | CK9: 0 | CL9: 39128.6 | CM9: 0 | CN9: 39128.6 | CO9: 139105.76 | CP9: 1027346.4 | CQ9: 4462.71 | CR9: 1170914.9 | CT9: Other Conv Cost | CU9: 0 | CV9: 105029.4 | CW9: 0 | CX9: 105029.4 | CY9: 139105.76 | CZ9: 1132375.8 | DA9: 4462.71 | DB9: 1275944.3 | DD9: Other Conv Cost | DE9: 0 | DF9: 74138.4 | DG9: 0 | DH9: 74138.4 | DI9: 139105.76 | DJ9: 1206514.2 | DK9: 4462.71 | DL9: 1350082.7 | DN9: Other Conv Cost | DO9: 0 | DP9: 123564 | DQ9: 18076.8 | DR9: 141640.8 | DS9: 139105.76 | DT9: 1330078.2 | DU9: 22539.51 | DV9: 1491723.5 | DX9: Other Conv Cost | DY9: 0 | DZ9: 123564 | EA9: 14203.2 | EB9: 137767.2 | EC9: 139105.76 | ED9: 1453642.2 | EE9: 36742.71 | EF9: 1629490.7 | EH9: Other Conv Cost | EI9: 0 | EJ9: 112310.1 | EK9: 21918.12 | EL9: 134228.22 | EM9: 139105.76 | EN9: 1565952.3 | EO9: 58660.83 | EP9: 1763718.9 | ER9: Other Conv Cost | ES9: 62080 | ET9: 98851.2 | EU9: 0 | EV9: 160931.2 | EW9: 207951.61 | EX9: 1658037.7 | EY9: 58660.83 | EZ9: 1924650.1 | FB9: Other Conv Cost | FC9: 0 | FD9: 74138.4 | FE9: 18012.24 | FF9: 92150.64 | FG9: 207951.61 | FH9: 1732176.1 | FI9: 76673.07 | FJ9: 2016800.7 | FL9: Other Conv Cost | FM9: 0 | FN9: 100816.8 | FO9: 30988.8 | FP9: 131805.6 | FQ9: 201185.76 | FR9: 1839758.7 | FS9: 107661.87 | FT9: 2148606.3 | FV9: Other Conv Cost | FW9: 0 | FX9: 139016.5 | FY9: 26631 | FZ9: 165647.5 | GA9: 201185.76 | GB9: 1978775.2 | GC9: 134292.87 | GD9: 2314253.8 | GF9: Other Conv Cost | GG9: 0 | GH9: 74138.4 | GI9: 13644 | GJ9: 7263 | GK9: 95045.4 | GL9: 201185.76 | GM9: 2052913.6 | GN9: 13644 | GO9: 141555.87 | GP9: 2409299.2 | GR9: Other Conv Cost | GS9: 58929.44 | GT9: 98851.2 | GU9: 18350.85 | GV9: 9684 | GW9: 185815.49 | GX9: 260115.2 | GY9: 2151764.8 | GZ9: 31994.85 | HA9: 151239.87 | HB9: 2595114.7 | HD9: Other Conv Cost | HE9: 46560 | HF9: 125395.2 | HG9: 7028.97 | HH9: 23160.9 | HI9: 202145.07 | HJ9: 306675.2 | HK9: 2277160 | HL9: 39023.82 | HM9: 174400.77 | HN9: 2797259.8 | HP9: Other Conv Cost | HQ9: 0 | HR9: 181506.69 | HS9: 3089.1 | HT9: 23459.49 | HU9: 208055.28 | HV9: 306675.2 | HW9: 2458666.7 | HX9: 42112.92 | HY9: 197860.26 | HZ9: 3005315.1 | IB9: Other Conv Cost | IC9: 0 | ID9: 1412.16 | IE9: 5295.6 | IF9: 20497.8 | IG9: 27205.56 | IH9: 306675.2 | II9: 2460078.9 | IJ9: 47408.52 | IK9: 218358.06 | IL9: 3032520.6 | IN9: Other Conv Cost | IO9: 0 | IP9: 123564 | IQ9: 2574.25 | IR9: 16140 | IS9: 142278.25 | IT9: 306675.2 | IU9: 2583642.9 | IV9: 49982.77 | IW9: 234498.06 | IX9: 3174798.9
B10: Margin | C10: 85505 | E10: 85505 | F10: 85505 | H10: 85505 | J10: Margin | K10: 0 | L10: 825.5 | M10: 825.5 | N10: 85505 | O10: 825.5 | P10: 86330.5 | R10: Margin | S10: 77788.63 | T10: 308394.85 | U10: -398.5 | V10: 385784.98 | W10: 163293.63 | X10: 309220.35 | Y10: -398.5 | Z10: 472115.48 | AB10: Margin | AC10: 0 | AD10: 140784 | AE10: 0 | AF10: 140784 | AG10: 163293.63 | AH10: 450004.35 | AI10: -398.5 | AJ10: 612899.48 | AL10: Margin | AM10: 0 | AN10: 152430.6 | AO10: 0 | AP10: 152430.6 | AQ10: 163293.63 | AR10: 602434.95 | AS10: -398.5 | AT10: 765330.08 | AV10: Margin | AW10: 0 | AX10: 290235.4 | AY10: 0 | AZ10: 290235.4 | BA10: 163293.63 | BB10: 892670.35 | BC10: -398.5 | BD10: 1055565.5 | BF10: Margin | BG10: 759300 | BH10: 180281 | BI10: 0 | BJ10: 939581 | BK10: 922593.63 | BL10: 1072951.3 | BM10: -398.5 | BN10: 1995146.5 | BP10: Margin | BQ10: 0 | BR10: 0 | BS10: -2224.23 | BT10: -2224.23 | BU10: 922593.63 | BV10: 1072951.3 | BW10: -2622.73 | BX10: 1992922.2 | BZ10: Margin | CA10: 1280500 | CB10: 336151.2 | CC10: 0 | CD10: 1616651.2 | CE10: 2203093.6 | CF10: 1409102.6 | CG10: -2622.73 | CH10: 3609573.5 | CJ10: Margin | CK10: 0 | CL10: 56844.2 | CM10: 0 | CN10: 56844.2 | CO10: 2203093.6 | CP10: 1465946.8 | CQ10: -2622.73 | CR10: 3666417.6 | CT10: Margin | CU10: 0 | CV10: 152421.15 | CW10: 0 | CX10: 152421.15 | CY10: 2203093.6 | CZ10: 1618367.9 | DA10: -2622.73 | DB10: 3818838.8 | DD10: Margin | DE10: 0 | DF10: 107553.6 | DG10: 0 | DH10: 107553.6 | DI10: 2203093.6 | DJ10: 1725921.5 | DK10: -2622.73 | DL10: 3926392.4 | DN10: Margin | DO10: 0 | DP10: 176635.2 | DQ10: -6854.4 | DR10: 169780.8 | DS10: 2203093.6 | DT10: 1902556.7 | DU10: -9477.13 | DV10: 4096173.2 | DX10: Margin | DY10: 0 | DZ10: 177996 | EA10: -5385.6 | EB10: 172610.4 | EC10: 2203093.6 | ED10: 2080552.7 | EE10: -14862.73 | EF10: 4268783.6 | EH10: Margin | EI10: 0 | EJ10: 160062.7 | EK10: -8310.96 | EL10: 151751.74 | EM10: 2203093.6 | EN10: 2240615.4 | EO10: -23173.69 | EP10: 4420535.3 | ER10: Margin | ES10: 1024400 | ET10: 143455.2 | EU10: 0 | EV10: 1167855.2 | EW10: 3234377.8 | EX10: 2377186.4 | EY10: -23173.69 | EZ10: 5588390.5 | FB10: Margin | FC10: 0 | FD10: 107553.6 | FE10: -6829.92 | FF10: 100723.68 | FG10: 3234377.8 | FH10: 2484740 | FI10: -30003.61 | FJ10: 5689114.2 | FL10: Margin | FM10: 0 | FN10: 65200.8 | FO10: -11750.4 | FP10: 53450.4 | FQ10: 3227493.6 | FR10: 2556825 | FS10: -41754.01 | FT10: 5742564.6 | FV10: Margin | FW10: 0 | FX10: 117651.1 | FY10: -10098 | FZ10: 107553.1 | GA10: 3227493.6 | GB10: 2674476.1 | GC10: -51852.01 | GD10: 5850117.7 | GF10: Margin | GG10: 0 | GH10: 107553.6 | GI10: -25059 | GJ10: -2754 | GK10: 79740.6 | GL10: 3227493.6 | GM10: 2782029.7 | GN10: -25059 | GO10: -54606.01 | GP10: 5929858.3 | GR10: Margin | GS10: 958112.44 | GT10: 143362.8 | GU10: 51229.5 | GV10: -3672 | GW10: 1149032.7 | GX10: 4185606.1 | GY10: 2925392.5 | GZ10: 26170.5 | HA10: -58278.01 | HB10: 7078891.1 | HD10: Margin | HE10: 768300 | HF10: 111022.8 | HG10: 12583.98 | HH10: -8782.2 | HI10: 883124.58 | HJ10: 4953906.1 | HK10: 3036415.3 | HL10: 38754.48 | HM10: -67060.21 | HN10: 7962015.6 | HP10: Margin | HQ10: 0 | HR10: 260550.69 | HS10: -15216.6 | HT10: -8057.37 | HU10: 237276.72 | HV10: 4956805.3 | HW10: 3296966 | HX10: 23537.88 | HY10: -75117.58 | HZ10: 8202191.6 | IB10: Margin | IC10: 0 | ID10: 1584.96 | IE10: -26085.6 | IF10: -7772.4 | IG10: -32273.04 | IH10: 4956805.3 | II10: 3298550.9 | IJ10: -2547.72 | IK10: -82889.98 | IL10: 8169918.6 | IN10: Margin | IO10: 0 | IP10: 172166.4 | IQ10: -12680.5 | IR10: -6120 | IS10: 153365.9 | IT10: 4956805.3 | IU10: 3470717.3 | IV10: -15228.22 | IW10: -89009.98 | IX10: 8323284.5
B11: Margin % | C11: 0.23131028 | E11: 0.23131028 | F11: 0.23131028 | H11: 0.23131028 | J11: Margin % | L11: 0.034467641 | M11: 0.034467641 | N11: 0.23131028 | O11: 0.034467641 | P11: 0.21933283 | R11: Margin % | S11: 0.22817835 | T11: 0.054796396 | U11: -0.021988027 | V11: 0.06443659 | W11: 0.22980766 | X11: 0.054710254 | Y11: -0.021988027 | Z11: 0.073991714 | AB11: Margin % | AD11: 0.058506479 | AF11: 0.058506479 | AG11: 0.22980766 | AH11: 0.055843854 | AI11: -0.021988027 | AJ11: 0.069751098 | AL11: Margin % | AN11: 0.059941665 | AP11: 0.059941665 | AQ11: 0.22980766 | AR11: 0.05682682 | AS11: -0.021988027 | AT11: 0.067549389 | AV11: Margin % | AX11: 0.058728462 | AZ11: 0.058728462 | BA11: 0.22980766 | BB11: 0.057431449 | BC11: -0.021988027 | BD11: 0.064870362 | BF11: Margin % | BG11: 0.34374109 | BH11: 0.059902936 | BJ11: 0.18004872 | BK11: 0.31601121 | BL11: 0.057832363 | BM11: -0.021988027 | BN11: 0.092838946 | BP11: Margin % | BS11: -0.023633038 | BT11: -0.023633038 | BU11: 0.31601121 | BV11: 0.057832363 | BW11: -0.023367414 | BX11: 0.092331092 | BZ11: Margin % | CA11: 0.34640408 | CB11: 0.059241692 | CD11: 0.17252039 | CE11: 0.33299246 | CF11: 0.058162443 | CG11: -0.023367414 | CH11: 0.11660598 | CJ11: Margin % | CL11: 0.060001123 | CN11: 0.060001123 | CO11: 0.33299246 | CP11: 0.058231638 | CQ11: -0.023367414 | CR11: 0.11076908 | CT11: Margin % | CV11: 0.059937949 | CX11: 0.059937949 | CY11: 0.33299246 | CZ11: 0.058388187 | DA11: -0.023367414 | DB11: 0.10701817 | DD11: Margin % | DF11: 0.059916891 | DH11: 0.059916891 | DI11: 0.33299246 | DJ11: 0.058481168 | DK11: -0.023367414 | DL11: 0.10468621 | DN11: Margin % | DP11: 0.05878735 | DQ11: -0.019778941 | DR11: 0.050662736 | DS11: 0.33299246 | DT11: 0.05850946 | DU11: -0.02065683 | DV11: 0.10011532 | DX11: Margin % | DZ11: 0.059367716 | EA11: -0.019778941 | EB11: 0.05277823 | EC11: 0.33299246 | ED11: 0.058581914 | EE11: -0.020329861 | EF11: 0.096504751 | EH11: Margin % | EJ11: 0.058940174 | EK11: -0.019778941 | EL11: 0.048392181 | EM11: 0.33299246 | EN11: 0.058607362 | EO11: -0.020128786 | EP11: 0.093225876 | ER11: Margin % | ES11: 0.34640408 | ET11: 0.059937949 | EV11: 0.21826478 | EW11: 0.33229274 | EX11: 0.058748013 | EY11: -0.020128786 | EZ11: 0.10625107 | FB11: Margin % | FD11: 0.059916891 | FE11: -0.019778941 | FF11: 0.047059243 | FG11: 0.33229274 | FH11: 0.058797663 | FI11: -0.020048065 | FJ11: 0.10388323 | FL11: Margin % | FN11: 0.030897714 | FO11: -0.019778941 | FP11: 0.025854109 | FQ11: 0.33713538 | FR11: 0.057418535 | FS11: -0.01997159 | FT11: 0.099845417 | FV11: Margin % | FX11: 0.038895847 | FY11: -0.019778941 | FZ11: 0.02812675 | GA11: 0.33713538 | GB11: 0.05624037 | GC11: -0.019933779 | GD11: 0.09558202 | GF11: Margin % | GH11: 0.059916891 | GI11: -0.060143934 | GJ11: -0.019778941 | GK11: 0.030861718 | GL11: 0.33713538 | GM11: 0.0563741 | GN11: -0.060143934 | GO11: -0.019925912 | GP11: 0.095519903 | GR11: Margin % | GS11: 0.34270195 | GT11: 0.059899343 | GU11: 0.062343231 | GV11: -0.019778941 | GW11: 0.18543133 | GX11: 0.33839359 | GY11: 0.056537162 | GZ11: 0.021132789 | HA11: -0.019916587 | HB11: 0.10367997 | HD11: Margin % | HE11: 0.34640408 | HF11: 0.037826622 | HG11: 0.042935257 | HH11: -0.019778941 | HI11: 0.14993413 | HJ11: 0.33961157 | HK11: 0.055532803 | HL11: 0.025305319 | HM11: -0.019898452 | HN11: 0.10735334 | HP11: Margin % | HR11: 0.061145874 | HS11: -0.23421793 | HT11: -0.018926884 | HU11: 0.049933958 | HV11: 0.33981033 | HW11: 0.055938613 | HX11: 0.01474395 | HY11: -0.019789489 | HZ11: 0.10393276 | IB11: Margin % | ID11: 0.034467641 | IE11: -0.23421793 | IF11: -0.019778941 | IG11: -0.05864407 | IH11: 0.33981033 | II11: 0.055921874 | IJ11: -0.0014917996 | IK11: -0.019788499 | IL11: 0.10280691 | IN11: Margin % | IP11: 0.057937585 | IQ11: -0.23421793 | IR11: -0.019778941 | IS11: 0.045984795 | IT11: 0.33981033 | IU11: 0.056018552 | IV11: -0.008642791 | IW11: -0.019787842 | IX11: 0.10051825
AB12: Rent & White Collar employees Salary doesn't form part of Other Conversion Cost | AL12: Rent & White Collar employees Salary doesn't form part of Other Conversion Cost | AV12: Rent & White Collar employees Salary doesn't form part of Other Conversion Cost | BF12: Rent & White Collar employees Salary doesn't form part of Other Conversion Cost | BP12: Rent & White Collar employees Salary doesn't form part of Other Conversion Cost | BZ12: Rent & White Collar employees Salary doesn't form part of Other Conversion Cost Sales of NPI not included | CJ12: Rent & White Collar employees Salary doesn't form part of Other Conversion Cost Sales of NPI not included | CT12: Rent & White Collar employees Salary doesn't form part of Other Conversion Cost Sales of NPI not included | DD12: Rent & White Collar employees Salary doesn't form part of Other Conversion Cost Sales of NPI not included | DN12: Rent & White Collar employees Salary doesn't form part of Other Conversion Cost Sales of NPI not included | DX12: Rent & White Collar employees Salary doesn't form part of Other Conversion Cost Sales of NPI not included | EH12: Rent & White Collar employees Salary doesn't form part of Other Conversion Cost Sales of NPI not included | ER12: Rent & White Collar employees Salary doesn't form part of Other Conversion Cost Sales of NPI not included | FB12: Rent & White Collar employees Salary doesn't form part of Other Conversion Cost Sales of NPI not included | FL12: Rent & White Collar employees Salary doesn't form part of Other Conversion Cost Sales of NPI not included | FV12: Rent & White Collar employees Salary doesn't form part of Other Conversion Cost Sales of NPI not included | GF12: Rent & White Collar employees Salary doesn't form part of Other Conversion Cost Sales of NPI not included | GR12: Rent & White Collar employees Salary doesn't form part of Other Conversion Cost Sales of NPI not included | HD12: Rent & White Collar employees Salary doesn't form part of Other Conversion Cost Sales of NPI not included | HP12: Rent & White Collar employees Salary doesn't form part of Other Conversion Cost Sales of NPI not included | IB12: Rent & White Collar employees Salary doesn't form part of Other Conversion Cost Sales of NPI not included | IN12: Rent & White Collar employees Salary doesn't form part of Other Conversion Cost Sales of NPI not included
IN14: ASP | IO14: =IO5/IO$4 -> #DIV/0! | IP14: =IP5/IP$4 -> 353.76 | IQ14: =IQ5/IQ$4 -> 309.37 | IR14: =IR5/IR$4 -> 154.71 | IS14: =IS5/IS$4 -> 315.38002 | IT14: =IT5/IT$4 -> 738.20732 | IU14: =IU5/IU$4 -> 358.72142 | IV14: =IV5/IV$4 -> 542.6413 | ... IX14: =IX5/IX$4 -> 368.37672
IN15: PGI pu | IO15: =IO6/IO$4 -> #DIV/0! | IP15: =IP6/IP$4 -> 333.264 | IQ15: =IQ6/IQ$4 -> 381.83 | IR15: =IR6/IR$4 -> 157.77 | IS15: =IS6/IS$4 -> 300.87734 | IT15: =IT6/IT$4 -> 487.35685 | IU15: =IU6/IU$4 -> 338.62636 | IV15: =IV6/IV$4 -> 547.33123 | ... IX15: =IX6/IX$4 -> 331.34814
IN16: GM pu | IO16: =IO14-IO15 -> #DIV/0! | IP16: =IP14-IP15 -> 20.496 | IQ16: =IQ14-IQ15 -> -72.46 | IR16: =IR14-IR15 -> -3.06 | IS16: =IS14-IS15 -> 14.502686 | IT16: =IT14-IT15 -> 250.85047 | IU16: =IU14-IU15 -> 20.095055 | IV16: =IV14-IV15 -> -4.6899353 | IW16: =IW14-IW15 -> -3.0631833 | IX16: =IX7/IX$4 -> 281.24837
IN17: BOM pu | IO17: =IO7/IO4 -> #DIV/0! | IP17: =IP7/IP4 -> 279.824 | IQ17: =IQ7/IQ4 -> 328.39 | IR17: =IR7/IR4 -> 137.27 | IS17: =IS7/IS4 -> 253.66713 | IT17: =IT7/IT4 -> 430.83685 | IU17: =IU7/IU4 -> 284.39293 | IV17: =IV7/IV4 -> 491.28794 | ... IX17: =IX7/IX4 -> 281.24837

Sheet Shared Dashboard - May
B2: AIPL SALES DB | C2: 45781 | H2: YTM - May-25 | N2: AIPL SALES DB | O2: 45782 | T2: YTM - May-25 | Z2: AIPL SALES DB | AA2: 45783 | AF2: YTM - May-25 | AL2: AIPL SALES DB | AM2: 45784 | AR2: YTM - May-25 | AX2: AIPL SALES DB | AY2: 45785 | BD2: YTM - May-25 | BJ2: AIPL SALES DB | BK2: 45786 | BP2: YTM - May-25 | BV2: AIPL SALES DB | BW2: 45788 | CB2: YTM - May-25 | CH2: AIPL SALES DB | CI2: 45789 | CN2: YTM - May-25 | CT2: AIPL SALES DB | CU2: 45790 | CZ2: YTM - May-25 | DF2: AIPL SALES DB | DG2: 45791 | DL2: YTM - May-25 | DR2: AIPL SALES DB | DS2: 45792 | DX2: YTM - May-25 | ED2: AIPL SALES DB | EE2: 45793 | EJ2: YTM - May-25 | EP2: AIPL SALES DB | EQ2: 45795 | EV2: YTM - May-25 | FB2: AIPL SALES DB | FC2: 45796 | FH2: YTM - May-25 | FN2: AIPL SALES DB | FO2: 45797 | FT2: YTM - May-25 | FZ2: AIPL SALES DB | GA2: 45798 | GG2: YTM - May-25 | GN2: AIPL SALES DB | GO2: 45799 | GU2: YTM - May-25 | HB2: AIPL SALES DB | HC2: 45800 | HI2: YTM - May-25 | HP2: AIPL SALES DB | HQ2: 45802 | HW2: YTM - May-25 | ID2: AIPL SALES DB | IE2: 45803 | IK2: YTM - May-25 | IR2: AIPL SALES DB | IS2: 45804 | IY2: YTM - May-25 | JF2: AIPL SALES DB | JG2: 45805 | JM2: YTM - May-25 | JT2: AIPL SALES DB | JU2: 45806 | KA2: YTM - May-25 | KH2: AIPL SALES DB | KI2: 45807 | KO2: YTM - May-25
B3: Product | C3: PCB - Ref | D3: PCB - CF | E3: PCB - MG | F3: Stator - CF | G3: Total | H3: PCB - Ref | I3: PCB - CF | J3: PCB - MG | K3: Stator - CF | L3: Total | N3: Product | O3: PCB - Ref | P3: PCB - CF | Q3: PCB - MG | R3: Stator - CF | S3: Total | T3: PCB - Ref | U3: PCB - CF | V3: PCB - MG | W3: Stator - CF | X3: Total | Z3: Product | AA3: PCB - Ref | AB3: PCB - CF | AC3: PCB - MG | AD3: Stator - CF | AE3: Total | AF3: PCB - Ref | AG3: PCB - CF | AH3: PCB - MG | AI3: Stator - CF | AJ3: Total | AL3: Product | AM3: PCB - Ref | AN3: PCB - CF | AO3: PCB - MG | AP3: Stator - CF | AQ3: Total | AR3: PCB - Ref | AS3: PCB - CF | AT3: PCB - MG | AU3: Stator - CF | AV3: Total | AX3: Product | AY3: PCB - Ref | AZ3: PCB - CF | BA3: PCB - MG | BB3: Stator - CF | BC3: Total | BD3: PCB - Ref | BE3: PCB - CF | BF3: PCB - MG | BG3: Stator - CF | BH3: Total | BJ3: Product | BK3: PCB - Ref | BL3: PCB - CF | BM3: PCB - MG | BN3: Stator - CF | BO3: Total | BP3: PCB - Ref | BQ3: PCB - CF | BR3: PCB - MG | BS3: Stator - CF | BT3: Total | BV3: Product | BW3: PCB - Ref | BX3: PCB - CF | BY3: PCB - MG | BZ3: Stator - CF | CA3: Total | CB3: PCB - Ref | CC3: PCB - CF | CD3: PCB - MG | CE3: Stator - CF | CF3: Total | CH3: Product | CI3: PCB - Ref | CJ3: PCB - CF | CK3: PCB - MG | CL3: Stator - CF | CM3: Total | CN3: PCB - Ref | CO3: PCB - CF | CP3: PCB - MG | CQ3: Stator - CF | CR3: Total | CT3: Product | CU3: PCB - Ref | CV3: PCB - CF | CW3: PCB - MG | CX3: Stator - CF | CY3: Total | CZ3: PCB - Ref | DA3: PCB - CF | DB3: PCB - MG | DC3: Stator - CF | DD3: Total | DF3: Product | DG3: PCB - Ref | DH3: PCB - CF | DI3: PCB - MG | DJ3: Stator - CF | DK3: Total | DL3: PCB - Ref | DM3: PCB - CF | DN3: PCB - MG | DO3: Stator - CF | DP3: Total | DR3: Product | DS3: PCB - Ref | DT3: PCB - CF | DU3: PCB - MG | DV3: Stator - CF | DW3: Total | DX3: PCB - Ref | DY3: PCB - CF | DZ3: PCB - MG | EA3: Stator - CF | EB3: Total | ED3: Product | EE3: PCB - Ref | EF3: PCB - CF | EG3: PCB - MG | EH3: Stator - CF | EI3: Total | EJ3: PCB - Ref | EK3: PCB - CF | EL3: PCB - MG | EM3: Stator - CF | EN3: Total | EP3: Product | EQ3: PCB - Ref | ER3: PCB - CF | ES3: PCB - MG | ET3: Stator - CF | EU3: Total | EV3: PCB - Ref | EW3: PCB - CF | EX3: PCB - MG | EY3: Stator - CF | EZ3: Total | FB3: Product | FC3: PCB - Ref | FD3: PCB - CF | FE3: PCB - MG | FF3: Stator - CF | FG3: Total | FH3: PCB - Ref | FI3: PCB - CF | FJ3: PCB - MG | FK3: Stator - CF | FL3: Total | FN3: Product | FO3: PCB - Ref | FP3: PCB - CF | FQ3: PCB - MG | FR3: Stator - CF | FS3: Total | FT3: PCB - Ref | FU3: PCB - CF | FV3: PCB - MG | FW3: Stator - CF | FX3: Total | FZ3: Product (INR in '000) | GA3: PCB Ref | GB3: PCB CF | GC3: PCB MG | GD3: Stator CF | GE3: Rotor Ref | GF3: Total | GG3: PCB Ref | GH3: PCB CF | GI3: PCB MG | GJ3: Stator CF | GK3: Rotor Ref | GL3: Total | GN3: Product (INR in '000) | GO3: PCB Ref | GP3: PCB CF | GQ3: PCB MG | GR3: Stator CF | GS3: Rotor Ref | GT3: Total | GU3: PCB Ref | GV3: PCB CF | GW3: PCB MG | GX3: Stator CF | GY3: Rotor Ref | GZ3: Total | HB3: Product (INR in '000) | HC3: PCB Ref | HD3: PCB CF | HE3: PCB MG | HF3: Stator CF | HG3: Rotor Ref | HH3: Total | HI3: PCB Ref | HJ3: PCB CF | HK3: PCB MG | HL3: Stator CF | HM3: Rotor Ref | HN3: Total | HP3: Product (INR in '000) | HQ3: PCB Ref | HR3: PCB CF | HS3: PCB MG | HT3: Stator CF | HU3: Rotor Ref | HV3: Total | HW3: PCB Ref | HX3: PCB CF | HY3: PCB MG | HZ3: Stator CF | IA3: Rotor Ref | IB3: Total | ID3: Product (INR in '000) | IE3: PCB Ref | IF3: PCB CF | IG3: PCB MG | IH3: Stator CF | II3: Rotor Ref | IJ3: Total | IK3: PCB Ref | IL3: PCB CF | IM3: PCB MG | IN3: Stator CF | IO3: Rotor Ref | IP3: Total | IR3: Product (INR in '000) | IS3: PCB Ref | IT3: PCB CF | IU3: PCB MG | IV3: Stator CF | IW3: Rotor Ref | IX3: Total | IY3: PCB Ref | IZ3: PCB CF | JA3: PCB MG | JB3: Stator CF | JC3: Rotor Ref | JD3: Total | JF3: Product (INR in '000) | JG3: PCB Ref | JH3: PCB CF | JI3: PCB MG | JJ3: Stator CF | JK3: Rotor Ref | JL3: Total | JM3: PCB Ref | JN3: PCB CF | JO3: PCB MG | JP3: Stator CF | JQ3: Rotor Ref | JR3: Total | JT3: Product (INR in '000) | JU3: PCB Ref | JV3: PCB CF | JW3: PCB MG | JX3: Stator CF | JY3: Rotor Ref | JZ3: Total | KA3: PCB Ref | KB3: PCB CF | KC3: PCB MG | KD3: Stator CF | KE3: Rotor Ref | KF3: Total | KH3: Product (INR in '000) | KI3: PCB Ref | KJ3: PCB CF | KK3: PCB MG | KL3: Stator CF | KM3: Rotor Ref | KN3: Total | KO3: PCB Ref | KP3: PCB CF | KQ3: PCB MG | KR3: Stator CF | KS3: Rotor Ref | KT3: Total
B4: Qty | C4: 2000 | D4: 5880 | E4: 630 | F4: 2374 | G4: 10884 | H4: 2000 | I4: 5880 | J4: 630 | K4: 2374 | L4: 10884 | N4: Qty | O4: 0 | P4: 11760 | Q4: 1435 | R4: 5420 | S4: 18615 | T4: 2000 | U4: 17640 | V4: 2065 | W4: 7794 | X4: 29499 | Z4: Qty | AA4: 0 | AB4: 6720 | AC4: 455 | AD4: 2000 | AE4: 9175 | AF4: 2000 | AG4: 24360 | AH4: 2520 | AI4: 9794 | AJ4: 38674 | AL4: Qty | AM4: 0 | AN4: 10080 | AO4: 980 | AP4: 0 | AQ4: 11060 | AR4: 2000 | AS4: 34440 | AT4: 3500 | AU4: 9794 | AV4: 49734 | AX4: Qty | AY4: 0 | AZ4: 13125 | BA4: 0 | BB4: 3360 | BC4: 16485 | BD4: 2000 | BE4: 47565 | BF4: 3500 | BG4: 13154 | BH4: 66219 | BJ4: Qty | BK4: 0 | BL4: 5880 | BM4: 613 | BN4: 1200 | BO4: 7693 | BP4: 2000 | BQ4: 53445 | BR4: 4113 | BS4: 14354 | BT4: 73912 | BV4: Qty | BW4: 0 | BX4: 7910 | BY4: 648 | BZ4: 3600 | CA4: 12158 | CB4: 2000 | CC4: 61355 | CD4: 4761 | CE4: 17954 | CF4: 86070 | CH4: Qty | CI4: 0 | CJ4: 9310 | CK4: 910 | CL4: 2880 | CM4: 13100 | CN4: 2000 | CO4: 70665 | CP4: 5671 | CQ4: 20834 | CR4: 99170 | CT4: Qty | CU4: 0 | CV4: 6790 | CW4: 617 | CX4: 2520 | CY4: 9927 | CZ4: 2000 | DA4: 77455 | DB4: 6288 | DC4: 23354 | DD4: 109097 | DF4: Qty | DG4: 0 | DH4: 4268 | DI4: 280 | DJ4: 2268 | DK4: 6816 | DL4: 2000 | DM4: 81723 | DN4: 6568 | DO4: 25622 | DP4: 115913 | DR4: Qty | DS4: 0 | DT4: 10850 | DU4: 175 | DV4: 2480 | DW4: 13505 | DX4: 2000 | DY4: 92573 | DZ4: 6743 | EA4: 28102 | EB4: 129418 | ED4: Qty | EE4: 0 | EF4: 10535 | EG4: 824 | EH4: 2448 | EI4: 13807 | EJ4: 2000 | EK4: 103108 | EL4: 7567 | EM4: 30550 | EN4: 143225 | EP4: Qty | EQ4: 0 | ER4: 5600 | ES4: 420 | ET4: 1720 | EU4: 7740 | EV4: 2000 | EW4: 108708 | EX4: 7987 | EY4: 32270 | EZ4: 150965 | FB4: Qty | FC4: 0 | FD4: 8225 | FE4: 910 | FF4: 3236 | FG4: 12371 | FH4: 2000 | FI4: 116933 | FJ4: 8897 | FK4: 35506 | FL4: 163336 | FN4: Qty | FO4: 0 | FP4: 6160 | FQ4: 770 | FR4: 1008 | FS4: 7938 | FT4: 2000 | FU4: 123093 | FV4: 9667 | FW4: 36514 | FX4: 171274 | FZ4: Qty (In Units) | GA4: 0 | GB4: 4515 | GC4: 1848 | GD4: 2016 | GE4: 40 | GF4: 8419 | GG4: 2000 | GH4: 127608 | GI4: 11515 | GJ4: 38530 | GK4: 40 | GL4: 179693 | GN4: Qty (In Units) | GO4: 3600 | GP4: 5740 | GQ4: 1365 | GR4: 3160 | GS4: 0 | GT4: 13865 | GU4: 5600 | GV4: 133348 | GW4: 12880 | GX4: 41690 | GY4: 40 | GZ4: 193558 | HB4: Qty (In Units) | HC4: 0 | HD4: 6615 | HE4: 70 | HF4: 3132 | HG4: 0 | HH4: 9817 | HI4: 5600 | HJ4: 139963 | HK4: 12950 | HL4: 44822 | HM4: 40 | HN4: 203375 | HP4: Qty (In Units) | HQ4: 0 | HR4: 7210 | HS4: 910 | HT4: 2208 | HU4: 0 | HV4: 10328 | HW4: 5600 | HX4: 147173 | HY4: 13860 | HZ4: 47030 | IA4: 40 | IB4: 213703 | ID4: Qty (In Units) | IE4: 0 | IF4: 8715 | IG4: 1680 | IH4: 3640 | II4: 0 | IJ4: 14035 | IK4: 5600 | IL4: 155888 | IM4: 15540 | IN4: 50670 | IO4: 40 | IP4: 227738 | IR4: Qty (In Units) | IS4: 0 | IT4: 5600 | IU4: 285 | IV4: 3056 | IW4: 0 | IX4: 8941 | IY4: 5600 | IZ4: 161488 | JA4: 15825 | JB4: 53726 | JC4: 40 | JD4: 236679 | JF4: Qty (In Units) | JG4: 3000 | JH4: 5110 | JI4: 215 | JJ4: 2976 | JK4: 0 | JL4: 11301 | JM4: 8600 | JN4: 166598 | JO4: 16040 | JP4: 56702 | JQ4: 40 | JR4: 247980 | JT4: Qty (In Units) | JU4: 0 | JV4: 2520 | JW4: 875 | JX4: 3048 | JY4: 0 | JZ4: 6443 | KA4: 8600 | KB4: 169118 | KC4: 16915 | KD4: 59750 | KE4: 40 | KF4: 254423 | KH4: Qty (In Units) | KI4: 0 | KJ4: 6370 | KK4: 0 | KL4: 3024 | KM4: 0 | KN4: 9394 | KO4: 8600 | KP4: 175488 | KQ4: 16915 | KR4: 62774 | KS4: 40 | KT4: 263817
B5: Sales ('000) | C5: 1472.62 | D5: 2314.116 | E5: 465.8094 | F5: 367.28154 | G5: 4619.8269 | H5: 1472.62 | I5: 2314.116 | J5: 465.8094 | K5: 367.28154 | L5: 4619.8269 | N5: Sales ('000) | O5: 0 | P5: 4178.3616 | Q5: 850.3054 | R5: 838.5282 | S5: 5867.1952 | T5: 1472.62 | U5: 6492.4776 | V5: 1316.1148 | W5: 1205.8097 | X5: 10487.022 | Z5: Sales ('000) | AA5: 0 | AB5: 2399.8464 | AC5: 392.3192 | AD5: 309.42 | AE5: 3101.5856 | AF5: 1472.62 | AG5: 8892.324 | AH5: 1708.434 | AI5: 1515.2297 | AJ5: 13588.608 | AL5: Sales ('000) | AM5: 0 | AN5: 3590.0928 | AO5: 632.14025 | AP5: 0 | AQ5: 4222.233 | AR5: 1472.62 | AS5: 12482.417 | AT5: 2340.5743 | AU5: 1515.2297 | AV5: 17810.841 | AX5: Sales ('000) | AY5: 0 | AZ5: 4784.0432 | BA5: 0 | BB5: 519.8256 | BC5: 5303.8688 | BD5: 1472.62 | BE5: 17266.46 | BF5: 2340.5743 | BG5: 2035.0553 | BH5: 23114.71 | BJ5: Sales ('000) | BK5: 0 | BL5: 2204.1684 | BM5: 340.57732 | BN5: 185.652 | BO5: 2730.3977 | BP5: 1472.62 | BQ5: 19470.628 | BR5: 2681.1516 | BS5: 2220.7073 | BT5: 25845.107 | BV5: Sales ('000) | BW5: 0 | BX5: 2927.1732 | BY5: 298.63057 | BZ5: 556.956 | CA5: 3782.7598 | CB5: 1472.62 | CC5: 22397.802 | CD5: 2979.7821 | CE5: 2777.6633 | CF5: 29627.867 | CH5: Sales ('000) | CI5: 0 | CJ5: 3318.9352 | CK5: 649.18525 | CL5: 445.5648 | CM5: 4413.6853 | CN5: 1472.62 | CO5: 25716.737 | CP5: 3628.9674 | CQ5: 3223.2281 | CR5: 34041.552 | CT5: Sales ('000) | CU5: 0 | CV5: 2519.1117 | CW5: 473.95073 | CX5: 389.8692 | CY5: 3382.9316 | CZ5: 1472.62 | DA5: 28235.849 | DB5: 4102.9181 | DC5: 3613.0973 | DD5: 37424.484 | DF5: Sales ('000) | DG5: 0 | DH5: 1528.7269 | DI5: 164.0254 | DJ5: 350.88228 | DK5: 2043.6346 | DL5: 1472.62 | DM5: 29764.575 | DN5: 4266.9435 | DO5: 3963.9796 | DP5: 39468.119 | DR5: Sales ('000) | DS5: 0 | DT5: 3934.3857 | DU5: 54.96575 | DV5: 383.6808 | DW5: 4373.0323 | DX5: 1472.62 | DY5: 33698.961 | DZ5: 4321.9093 | EA5: 4347.6604 | EB5: 43841.151 | ED5: Sales ('000) | EE5: 0 | EF5: 4015.5847 | EG5: 253.52714 | EH5: 378.73008 | EI5: 4647.8419 | EJ5: 1472.62 | EK5: 37714.546 | EL5: 4575.4364 | EM5: 4726.3905 | EN5: 48488.993 | EP5: Sales ('000) | EQ5: 0 | ER5: 2101.6492 | ES5: 285.3998 | ET5: 276.621 | EU5: 2663.67 | EV5: 1472.62 | EW5: 39816.195 | EX5: 4860.8362 | EY5: 5003.0115 | EZ5: 51152.663 | FB5: Sales ('000) | FC5: 0 | FD5: 3090.521 | FE5: 281.6919 | FF5: 500.64156 | FG5: 3872.8545 | FH5: 1472.62 | FI5: 42906.716 | FJ5: 5142.5281 | FK5: 5503.6531 | FL5: 55025.517 | FN5: Sales ('000) | FO5: 0 | FP5: 2303.2506 | FQ5: 297.58785 | FR5: 155.94768 | FS5: 2756.7861 | FT5: 1472.62 | FU5: 45209.967 | FV5: 5440.116 | FW5: 5659.6007 | FX5: 57782.303 | FZ5: Sales | GA5: 0 | GB5: 1608.0624 | GC5: 927.54452 | GD5: 311.89536 | GE5: 5.8696 | GF5: 2853.3719 | GG5: 1472.62 | GH5: 46818.029 | GI5: 6367.6605 | GJ5: 5971.4961 | GK5: 5.8696 | GL5: 60635.675 | GN5: Sales | GO5: 2650.716 | GP5: 2119.9234 | GQ5: 634.56435 | GR5: 488.8836 | GS5: 0 | GT5: 5894.0873 | GU5: 4123.336 | GV5: 48937.952 | GW5: 7002.2248 | GX5: 6460.3797 | GY5: 5.8696 | GZ5: 66529.763 | HB5: Sales | HC5: 0 | HD5: 2493.7934 | HE5: 41.17155 | HF5: 484.55172 | HG5: 0 | HH5: 3019.5167 | HI5: 4123.336 | HJ5: 51431.746 | HK5: 7043.3964 | HL5: 6944.9314 | HM5: 5.8696 | HN5: 69549.279 | HP5: Sales | HQ5: 0 | HR5: 2688.7336 | HS5: 330.72165 | HT5: 341.59968 | HU5: 0 | HV5: 3361.0549 | HW5: 4123.336 | HX5: 54120.479 | HY5: 7374.118 | HZ5: 7286.5311 | IA5: 5.8696 | IB5: 72910.334 | ID5: Sales | IE5: 0 | IF5: 3335.0744 | IG5: 632.3702 | IH5: 563.1444 | II5: 0 | IJ5: 4530.589 | IK5: 4123.336 | IL5: 57455.554 | IM5: 8006.4882 | IN5: 7849.6755 | IO5: 5.8696 | IP5: 77440.923 | IR5: Sales | IS5: 0 | IT5: 2136.736 | IU5: 99.32225 | IV5: 472.79376 | IW5: 0 | IX5: 2708.852 | IY5: 4123.336 | IZ5: 59592.29 | JA5: 8105.8105 | JB5: 8322.4693 | JC5: 5.8696 | JD5: 80149.775 | JF5: Sales | JG5: 2217.93 | JH5: 1939.9926 | JI5: 132.1116 | JJ5: 460.41696 | JK5: 0 | JL5: 4750.4512 | JM5: 6341.266 | JN5: 61532.282 | JO5: 8237.9221 | JP5: 8782.8862 | JQ5: 5.8696 | JR5: 84900.226 | JT5: Sales | JU5: 0 | JV5: 964.1982 | JW5: 381.57 | JX5: 471.55608 | JY5: 0 | JZ5: 1817.3243 | KA5: 6341.266 | KB5: 62496.481 | KC5: 8619.4921 | KD5: 9254.4423 | KE5: 5.8696 | KF5: 86717.551 | KH5: Sales | KI5: 0 | KJ5: 2268.7392 | KK5: 0 | KL5: 467.84304 | KM5: 0 | KN5: 2736.5822 | KO5: 6341.266 | KP5: 64765.22 | KQ5: 8619.4921 | KR5: 9722.2853 | KS5: 5.8696 | KT5: 89454.133
B6: COGS ('000) | C6: 951.44 | D6: 2114.8176 | E6: 404.4719 | F6: 329.13136 | G6: 3799.8609 | H6: 951.44 | I6: 2114.8176 | J6: 404.4719 | K6: 329.13136 | L6: 3799.8609 | N6: COGS ('000) | O6: 0 | P6: 3851.1984 | Q6: 750.01815 | R6: 751.4288 | S6: 5352.6453 | T6: 951.44 | U6: 5966.016 | V6: 1154.4901 | W6: 1080.5602 | X6: 9152.5062 | Z6: COGS ('000) | AA6: 0 | AB6: 2212.1904 | AC6: 337.55995 | AD6: 277.28 | AE6: 2827.0303 | AF6: 951.44 | AG6: 8178.2064 | AH6: 1492.05 | AI6: 1357.8402 | AJ6: 11979.537 | AL6: COGS ('000) | AM6: 0 | AN6: 3306.6432 | AO6: 554.0255 | AP6: 0 | AQ6: 3860.6687 | AR6: 951.44 | AS6: 11484.85 | AT6: 2046.0755 | AU6: 1357.8402 | AV6: 15840.205 | AX6: COGS ('000) | AY6: 0 | AZ6: 4402.6489 | BA6: 0 | BB6: 465.8304 | BC6: 4868.4793 | BD6: 951.44 | BE6: 15887.499 | BF6: 2046.0755 | BG6: 1823.6706 | BH6: 20708.685 | BJ6: COGS ('000) | BK6: 0 | BL6: 2021.8716 | BM6: 301.97577 | BN6: 166.368 | BO6: 2490.2154 | BP6: 951.44 | BQ6: 17909.37 | BR6: 2348.0513 | BS6: 1990.0386 | BT6: 23198.9 | BV6: COGS ('000) | BW6: 0 | BX6: 2687.8131 | BY6: 268.51176 | BZ6: 499.104 | CA6: 3455.4289 | CB6: 951.44 | CC6: 20597.183 | CD6: 2616.563 | CE6: 2489.1426 | CF6: 26654.329 | CH6: COGS ('000) | CI6: 0 | CJ6: 3058.0098 | CK6: 565.012 | CL6: 399.2832 | CM6: 4022.305 | CN6: 951.44 | CO6: 23655.193 | CP6: 3181.575 | CQ6: 2888.4258 | CR6: 30676.634 | CT6: COGS ('000) | CU6: 0 | CV6: 2312.6089 | CW6: 410.55703 | CX6: 349.3728 | CY6: 3072.5387 | CZ6: 951.44 | DA6: 25967.802 | DB6: 3592.1321 | DC6: 3237.7986 | DD6: 33749.173 | DF6: COGS ('000) | DG6: 0 | DH6: 1407.603 | DI6: 144.8104 | DJ6: 314.43552 | DK6: 1866.8489 | DL6: 951.44 | DM6: 27375.405 | DN6: 3736.9425 | DO6: 3552.2341 | DP6: 35616.022 | DR6: COGS ('000) | DS6: 0 | DT6: 3624.3172 | DU6: 51.3835 | DV6: 343.8272 | DW6: 4019.5279 | DX6: 951.44 | DY6: 30999.722 | DZ6: 3788.326 | EA6: 3896.0613 | EB6: 39635.549 | ED6: COGS ('000) | EE6: 0 | EF6: 3683.6338 | EG6: 234.75981 | EH6: 339.39072 | EI6: 4257.7843 | EJ6: 951.44 | EK6: 34683.356 | EL6: 4023.0858 | EM6: 4235.452 | EN6: 43893.334 | EP6: COGS ('000) | EQ6: 0 | ER6: 1929.9882 | ES6: 248.836 | ET6: 248.2368 | EU6: 2427.061 | EV6: 951.44 | EW6: 36613.344 | EX6: 4271.9218 | EY6: 4483.6888 | EZ6: 46320.395 | FB6: COGS ('000) | FC6: 0 | FD6: 2839.2388 | FE6: 266.18795 | FF6: 448.63904 | FG6: 3554.0658 | FH6: 951.44 | FI6: 39452.583 | FJ6: 4538.1097 | FK6: 4932.3278 | FL6: 49874.461 | FN6: COGS ('000) | FO6: 0 | FP6: 2116.4587 | FQ6: 272.713 | FR6: 139.74912 | FS6: 2528.9209 | FT6: 951.44 | FU6: 41569.042 | FV6: 4810.8227 | FW6: 5072.077 | FX6: 52403.381 | FZ6: COGS | GA6: 0 | GB6: 1481.1037 | GC6: 808.34397 | GD6: 279.49824 | GE6: 3.629 | GF6: 2572.575 | GG6: 951.44 | GH6: 43050.146 | GI6: 5619.1667 | GJ6: 5351.5752 | GK6: 3.629 | GL6: 54975.956 | GN6: COGS | GO6: 1712.592 | GP6: 1948.822 | GQ6: 561.14275 | GR6: 438.1024 | GS6: 0 | GT6: 4660.6592 | GU6: 2664.032 | GV6: 44998.968 | GW6: 6180.3094 | GX6: 5789.6776 | GY6: 3.629 | GZ6: 59636.616 | HB6: COGS | HC6: 0 | HD6: 2290.105 | HE6: 36.24285 | HF6: 434.22048 | HG6: 0 | HH6: 2760.5683 | HI6: 2664.032 | HJ6: 47289.073 | HK6: 6216.5523 | HL6: 6223.8981 | HM6: 3.629 | HN6: 62397.184 | HP6: COGS | HQ6: 0 | HR6: 2476.5216 | HS6: 295.21275 | HT6: 306.11712 | HU6: 0 | HV6: 3077.8515 | HW6: 2664.032 | HX6: 49765.594 | HY6: 6511.765 | HZ6: 6530.0152 | IA6: 3.629 | IB6: 65475.035 | ID6: COGS | IE6: 0 | IF6: 3060.379 | IG6: 562.9533 | IH6: 504.6496 | II6: 0 | IJ6: 4127.9819 | IK6: 2664.032 | IL6: 52825.973 | IM6: 7074.7183 | IN6: 7034.6648 | IO6: 3.629 | IP6: 69603.017 | IR6: COGS | IS6: 0 | IT6: 1961.064 | IU6: 92.36535 | IV6: 423.68384 | IW6: 0 | IX6: 2477.1132 | IY6: 2664.032 | IZ6: 54787.037 | JA6: 7167.0837 | JB6: 7458.3486 | JC6: 3.629 | JD6: 72080.13 | JF6: COGS | JG6: 1427.16 | JH6: 1780.9246 | JI6: 114.49285 | JJ6: 412.59264 | JK6: 0 | JL6: 3735.1701 | JM6: 4091.192 | JN6: 56567.962 | JO6: 7281.5765 | JP6: 7870.9413 | JQ6: 3.629 | JR6: 75815.301 | JT6: COGS | JU6: 0 | JV6: 884.8035 | JW6: 334.05925 | JX6: 422.57472 | JY6: 0 | JZ6: 1641.4375 | KA6: 4091.192 | KB6: 57452.765 | KC6: 7615.6358 | KD6: 8293.516 | KE6: 3.629 | KF6: 77456.738 | KH6: COGS | KI6: 0 | KJ6: 2089.6148 | KK6: 0 | KL6: 419.24736 | KM6: 0 | KN6: 2508.8622 | KO6: 4091.192 | KP6: 59542.38 | KQ6: 7615.6358 | KR6: 8712.7634 | KS6: 3.629 | KT6: 79965.6
B7: BOM cost ('000) | C7: 847.34 | D7: 1824.1104 | E7: 370.7571 | F7: 313.46296 | G7: 3355.6705 | H7: 847.34 | I7: 1824.1104 | J7: 370.7571 | K7: 313.46296 | L7: 3355.6705 | N7: BOM cost ('000) | O7: 0 | P7: 3269.784 | Q7: 675.22035 | R7: 715.6568 | S7: 4660.6611 | T7: 847.34 | U7: 5093.8944 | V7: 1045.9774 | W7: 1029.1198 | X7: 8016.3316 | Z7: BOM cost ('000) | AA7: 0 | AB7: 1879.9536 | AC7: 312.68055 | AD7: 264.08 | AE7: 2456.7141 | AF7: 847.34 | AG7: 6973.848 | AH7: 1358.658 | AI7: 1293.1998 | AJ7: 10473.046 | AL7: BOM cost ('000) | AM7: 0 | AN7: 2808.288 | AO7: 502.4565 | AP7: 0 | AQ7: 3310.7445 | AR7: 847.34 | AS7: 9782.136 | AT7: 1861.1145 | AU7: 1293.1998 | AV7: 13783.79 | AX7: BOM cost ('000) | AY7: 0 | AZ7: 3753.749 | BA7: 0 | BB7: 443.6544 | BC7: 4197.4034 | BD7: 847.34 | BE7: 13535.885 | BF7: 1861.1145 | BG7: 1736.8542 | BH7: 17981.194 | BJ7: BOM cost ('000) | BK7: 0 | BL7: 1731.1644 | BM7: 270.23853 | BN7: 158.448 | BO7: 2159.8509 | BP7: 847.34 | BQ7: 15267.049 | BR7: 2131.353 | BS7: 1895.3022 | BT7: 20141.045 | BV7: BOM cost ('000) | BW7: 0 | BX7: 2296.7427 | BY7: 235.87352 | BZ7: 475.344 | CA7: 3007.9602 | CB7: 847.34 | CC7: 17563.792 | CD7: 2367.2265 | CE7: 2370.6462 | CF7: 23149.005 | CH7: BOM cost ('000) | CI7: 0 | CJ7: 2597.7049 | CK7: 516.537 | CL7: 380.2752 | CM7: 3494.5171 | CN7: 847.34 | CO7: 20161.497 | CP7: 2883.7635 | CQ7: 2750.9214 | CR7: 26643.522 | CT7: BOM cost ('000) | CU7: 0 | CV7: 1976.9113 | CW7: 377.36967 | CX7: 332.7408 | CY7: 2687.0218 | CZ7: 847.34 | DA7: 22138.408 | DB7: 3261.1332 | DC7: 3083.6622 | DD7: 29330.544 | DF7: BOM cost ('000) | DG7: 0 | DH7: 1196.5931 | DI7: 130.2336 | DJ7: 299.46672 | DK7: 1626.2934 | DL7: 847.34 | DM7: 23335.001 | DN7: 3391.3668 | DO7: 3383.1289 | DP7: 30956.837 | DR7: BOM cost ('000) | DS7: 0 | DT7: 3087.8932 | DU7: 42.917 | DV7: 327.4592 | DW7: 3458.2694 | DX7: 847.34 | DY7: 26422.895 | DZ7: 3434.2838 | EA7: 3710.5881 | EB7: 34415.106 | ED7: BOM cost ('000) | EE7: 0 | EF7: 3162.7834 | EG7: 195.61107 | EH7: 323.23392 | EI7: 3681.6284 | EJ7: 847.34 | EK7: 29585.678 | EL7: 3629.8949 | EM7: 4033.822 | EN7: 38096.735 | EP7: BOM cost ('000) | EQ7: 0 | ER7: 1653.1242 | ES7: 226.7524 | ET7: 236.8848 | EU7: 2116.7614 | EV7: 847.34 | EW7: 31238.802 | EX7: 3856.6473 | EY7: 4270.7068 | EZ7: 40213.496 | FB7: BOM cost ('000) | FC7: 0 | FD7: 2432.5948 | FE7: 221.23465 | FF7: 427.28144 | FG7: 3081.1109 | FH7: 847.34 | FI7: 33671.397 | FJ7: 4077.8819 | FK7: 4697.9882 | FL7: 43294.607 | FN7: BOM cost ('000) | FO7: 0 | FP7: 1811.9084 | FQ7: 234.3908 | FR7: 133.09632 | FS7: 2179.3955 | FT7: 847.34 | FU7: 35483.305 | FV7: 4312.2727 | FW7: 4831.0846 | FX7: 45474.003 | FZ7: BOM cost | GA7: 0 | GB7: 1257.8821 | GC7: 735.34783 | GD7: 266.19264 | GE7: 3.365 | GF7: 2262.7876 | GG7: 847.34 | GH7: 36741.187 | GI7: 5047.6206 | GJ7: 5097.2772 | GK7: 3.365 | GL7: 47736.79 | GN7: BOM cost | GO7: 1525.212 | GP7: 1665.0364 | GQ7: 501.71415 | GR7: 417.2464 | GS7: 0 | GT7: 4109.209 | GU7: 2372.552 | GV7: 38406.224 | GW7: 5549.3347 | GX7: 5514.5236 | GY7: 3.365 | GZ7: 51845.999 | HB7: BOM cost | HC7: 0 | HD7: 1963.0593 | HE7: 32.63575 | HF7: 413.54928 | HG7: 0 | HH7: 2409.2444 | HI7: 2372.552 | HJ7: 40369.283 | HK7: 5581.9705 | HL7: 5928.0729 | HM7: 3.365 | HN7: 54255.244 | HP7: BOM cost | HQ7: 0 | HR7: 2119.5769 | HS7: 260.46265 | HT7: 291.54432 | HU7: 0 | HV7: 2671.5839 | HW7: 2372.552 | HX7: 42488.86 | HY7: 5842.4331 | HZ7: 6219.6172 | IA7: 3.365 | IB7: 56926.828 | ID7: BOM cost | IE7: 0 | IF7: 2629.5094 | IG7: 498.4231 | IH7: 480.6256 | II7: 0 | IJ7: 3608.5581 | IK7: 2372.552 | IL7: 45118.37 | IM7: 6340.8562 | IN7: 6700.2428 | IO7: 3.365 | IP7: 60535.386 | IR7: BOM cost | IS7: 0 | IT7: 1684.2 | IU7: 78.19135 | IV7: 403.51424 | IW7: 0 | IX7: 2165.9056 | IY7: 2372.552 | IZ7: 46802.57 | JA7: 6419.0476 | JB7: 7103.757 | JC7: 3.365 | JD7: 62701.291 | JF7: BOM cost | JG7: 1271.01 | JH7: 1528.2862 | JI7: 104.98085 | JJ7: 392.95104 | JK7: 0 | JL7: 3297.2281 | JM7: 3643.562 | JN7: 48330.856 | JO7: 6524.0284 | JP7: 7496.7081 | JQ7: 3.365 | JR7: 65998.519 | JT7: BOM cost | JU7: 0 | JV7: 760.2147 | JW7: 301.92365 | JX7: 402.45792 | JY7: 0 | JZ7: 1464.5963 | KA7: 3643.562 | KB7: 49091.07 | KC7: 6825.9521 | KD7: 7899.166 | KE7: 3.365 | KF7: 67463.116 | KH7: BOM cost | KI7: 0 | KJ7: 1774.682 | KK7: 0 | KL7: 399.28896 | KM7: 0 | KN7: 2173.971 | KO7: 3643.562 | KP7: 50865.752 | KQ7: 6825.9521 | KR7: 8298.455 | KS7: 3.365 | KT7: 69637.087
